<?xml version="1.0" ?>
<!-- =================================================================================== -->
<!-- |    This document was autogenerated by xacro from /home/timo/catkin_ws/src/rotors_simulator/rotors_description/urdf/odonata.xacro | -->
<!-- |    EDITING THIS FILE BY HAND IS NOT RECOMMENDED                                 | -->
<!-- =================================================================================== -->
<!--
  Copyright 2015 Fadri Furrer, ASL, ETH Zurich, Switzerland
  Copyright 2015 Michael Burri, ASL, ETH Zurich, Switzerland
  Copyright 2015 Mina Kamel, ASL, ETH Zurich, Switzerland
  Copyright 2015 Janosch Nikolic, ASL, ETH Zurich, Switzerland
  Copyright 2015 Markus Achtelik, ASL, ETH Zurich, Switzerland

  2017 modified by Timo Muller, ASL, ETH Zurich, Switzerland

  Licensed under the Apache License, Version 2.0 (the "License");
  you may not use this file except in compliance with the License.
  You may obtain a copy of the License at

  http://www.apache.org/licenses/LICENSE-2.0

  Unless required by applicable law or agreed to in writing, software
  distributed under the License is distributed on an "AS IS" BASIS,
  WITHOUT WARRANTIES OR CONDITIONS OF ANY KIND, either express or implied.
  See the License for the specific language governing permissions and
  limitations under the License.
-->
<robot name="odonata" xmlns:xacro="http://ros.org/wiki/xacro">
  <!-- [m] -->
  <!-- [m] -->
  <!-- main fuselage -->
  <link name="base_link">
    <inertial>
      <mass value="2"/>
      <!-- [kg] -->
      <origin xyz="0 0 0"/>
      <inertia ixx="1.0" ixy="0.0" ixz="0.0" iyy="1.0" iyz="0.0" izz="1.0"/>
    </inertial>
    <visual>
      <origin rpy="0 0 0" xyz="0 0 0"/>
      <geometry>
        <mesh filename="package://rotors_description/meshes/odonata/main.stl" scale="0.001 0.001 -0.001"/>
      </geometry>
    </visual>
    <!-- collision element comes here (optional)-->
  </link>
  <!-- **************************************************************************** -->
  <!-- left arm -->
  <link name="left_arm">
    <inertial>
      <mass value="0"/>
      <!-- [kg] -->
      <origin xyz="0 0 0"/>
      <inertia ixx="0.0" ixy="0.0" ixz="0.0" iyy="0.0" iyz="0.0" izz="0.0"/>
    </inertial>
    <visual>
      <origin rpy="0 0 0" xyz="0 0 0"/>
      <geometry>
        <mesh filename="package://rotors_description/meshes/odonata/left_arm.stl" scale="0.001 0.001 -0.001"/>
      </geometry>
    </visual>
    <!-- collision element comes here (optional)-->
  </link>
  <joint name="base_to_left_arm" type="revolute">
    <axis xyz="0 1 0"/>
    <limit effort="1000.0" lower="-2.87979326579" upper="2.87979326579" velocity="0.5"/>
    <parent link="base_link"/>
    <child link="left_arm"/>
    <origin xyz="0 0 0"/>
  </joint>
  <!-- **************************************************************************** -->
  <!-- right arm -->
  <link name="right_arm">
    <inertial>
      <mass value="0"/>
      <!-- [kg] -->
      <origin xyz="0 0 0"/>
      <inertia ixx="0.0" ixy="0.0" ixz="0.0" iyy="0.0" iyz="0.0" izz="0.0"/>
    </inertial>
    <visual>
      <origin rpy="0 0 0" xyz="0 0 0"/>
      <geometry>
        <mesh filename="package://rotors_description/meshes/odonata/right_arm.stl" scale="0.001 0.001 -0.001"/>
      </geometry>
    </visual>
    <!-- collision element comes here (optional)-->
  </link>
  <joint name="base_to_right_arm" type="revolute">
    <axis xyz="0 1 0"/>
    <limit effort="1000.0" lower="-2.87979326579" upper="2.87979326579" velocity="0.5"/>
    <parent link="base_link"/>
    <child link="right_arm"/>
    <origin xyz="0 0 0"/>
  </joint>
  <!-- **************************************************************************** -->
  <!-- left motor -->
  <link name="left_motor">
    <inertial>
      <mass value="0.5"/>
      <!-- [kg] -->
      <origin xyz="0 -0.345 0"/>
      <inertia ixx="1.0" ixy="0.0" ixz="0.0" iyy="1.0" iyz="0.0" izz="1.0"/>
    </inertial>
    <visual>
      <origin rpy="0 0 0" xyz="0 -0.345 0"/>
      <geometry>
        <mesh filename="package://rotors_description/meshes/odonata/left_motor.stl" scale="0.001 0.001 -0.001"/>
      </geometry>
    </visual>
    <!-- collision element comes here (optional)-->
  </link>
  <joint name="left_arm_to_motor" type="revolute">
    <axis xyz="1 0 0"/>
    <limit effort="1000.0" lower="-0.174532925199" upper="0.174532925199" velocity="0.5"/>
    <parent link="left_arm"/>
    <child link="left_motor"/>
    <origin xyz="0 0.345 0"/>
  </joint>
  <!-- **************************************************************************** -->
  <!-- right motor -->
  <link name="right_motor">
    <inertial>
      <mass value="0.5"/>
      <!-- [kg] -->
      <origin xyz="0 0.345 0"/>
      <inertia ixx="1.0" ixy="0.0" ixz="0.0" iyy="1.0" iyz="0.0" izz="1.0"/>
    </inertial>
    <visual>
      <origin rpy="0 0 0" xyz="0 0.345 0"/>
      <geometry>
        <mesh filename="package://rotors_description/meshes/odonata/right_motor.stl" scale="0.001 0.001 -0.001"/>
      </geometry>
    </visual>
    <!-- collision element comes here (optional)-->
  </link>
  <joint name="right_arm_to_motor" type="revolute">
    <axis xyz="1 0 0"/>
    <limit effort="1000.0" lower="-0.174532925199" upper="0.174532925199" velocity="0.5"/>
    <parent link="right_arm"/>
    <child link="right_motor"/>
    <origin xyz="0 -0.345 0"/>
  </joint>
  <!-- **************************************************************************** -->
  <joint name="$odonata/rotor_0_joint" type="continuous">
    <origin rpy="0 0 0" xyz="0 0 0.073"/>
    <axis xyz="0 0 1"/>
    <!-- TODO(ff): not currently set because it's not yet supported -->
    <!-- <limit effort="2000" velocity="${max_rot_velocity}" /> -->
    <parent link="left_motor"/>
    <child link="$odonata/rotor_0"/>
  </joint>
  <link name="$odonata/rotor_0">
    <inertial>
      <mass value="0.005"/>
      <!-- [kg] -->
      <inertia ixx="9.7499961e-07" ixy="0.0" ixz="0.0" iyy="0.000172080097835" iyz="0.0" izz="0.000172980097475"/>
    </inertial>
    <visual>
      <geometry>
        <mesh filename="package://rotors_description/meshes/propeller_ccw.dae" scale="0.2032 0.2032 0.2032"/>
        <!-- The propeller meshes have a radius of 1m -->
        <!-- <box size="${2*radius_rotor} 0.01 0.005"/> -->
      </geometry>
    </visual>
    <collision>
      <geometry>
        <cylinder length="0.005" radius="0.2032"/>
        <!-- [m] -->
      </geometry>
    </collision>
  </link>
  <gazebo>
    <plugin filename="librotors_gazebo_motor_model.so" name="$odonata_left_top_motor_model">
      <robotNamespace>$odonata</robotNamespace>
      <jointName>$odonata/rotor_0_joint</jointName>
      <linkName>$odonata/rotor_0</linkName>
      <turningDirection>ccw</turningDirection>
      <timeConstantUp>0.0125</timeConstantUp>
      <timeConstantDown>0.025</timeConstantDown>
      <maxRotVelocity>838</maxRotVelocity>
      <motorConstant>8.54858e-06</motorConstant>
      <momentConstant>0.016</momentConstant>
      <commandSubTopic>gazebo/command/motor_speed</commandSubTopic>
      <motorNumber>0</motorNumber>
      <rotorDragCoefficient>8.06428e-05</rotorDragCoefficient>
      <rollingMomentCoefficient>1e-06</rollingMomentCoefficient>
      <motorSpeedPubTopic>motor_speed/0</motorSpeedPubTopic>
      <rotorVelocitySlowdownSim>10</rotorVelocitySlowdownSim>
    </plugin>
  </gazebo>
  <gazebo reference="$odonata/rotor_0">
    <material>Gazebo/Red</material>
  </gazebo>
  <joint name="$odonata/rotor_1_joint" type="continuous">
    <origin rpy="0 0 0" xyz="0 0 -0.053"/>
    <axis xyz="0 0 1"/>
    <!-- TODO(ff): not currently set because it's not yet supported -->
    <!-- <limit effort="2000" velocity="${max_rot_velocity}" /> -->
    <parent link="left_motor"/>
    <child link="$odonata/rotor_1"/>
  </joint>
  <link name="$odonata/rotor_1">
    <inertial>
      <mass value="0.005"/>
      <!-- [kg] -->
      <inertia ixx="9.7499961e-07" ixy="0.0" ixz="0.0" iyy="0.000172080097835" iyz="0.0" izz="0.000172980097475"/>
    </inertial>
    <visual>
      <geometry>
        <mesh filename="package://rotors_description/meshes/propeller_cw.dae" scale="0.2032 0.2032 0.2032"/>
        <!-- The propeller meshes have a radius of 1m -->
        <!-- <box size="${2*radius_rotor} 0.01 0.005"/> -->
      </geometry>
    </visual>
    <collision>
      <geometry>
        <cylinder length="0.005" radius="0.2032"/>
        <!-- [m] -->
      </geometry>
    </collision>
  </link>
  <gazebo>
    <plugin filename="librotors_gazebo_motor_model.so" name="$odonata_left_bottom_motor_model">
      <robotNamespace>$odonata</robotNamespace>
      <jointName>$odonata/rotor_1_joint</jointName>
      <linkName>$odonata/rotor_1</linkName>
      <turningDirection>cw</turningDirection>
      <timeConstantUp>0.0125</timeConstantUp>
      <timeConstantDown>0.025</timeConstantDown>
      <maxRotVelocity>838</maxRotVelocity>
      <motorConstant>8.54858e-06</motorConstant>
      <momentConstant>0.016</momentConstant>
      <commandSubTopic>gazebo/command/motor_speed</commandSubTopic>
      <motorNumber>1</motorNumber>
      <rotorDragCoefficient>8.06428e-05</rotorDragCoefficient>
      <rollingMomentCoefficient>1e-06</rollingMomentCoefficient>
      <motorSpeedPubTopic>motor_speed/1</motorSpeedPubTopic>
      <rotorVelocitySlowdownSim>10</rotorVelocitySlowdownSim>
    </plugin>
  </gazebo>
  <gazebo reference="$odonata/rotor_1">
    <material>Gazebo/Blue</material>
  </gazebo>
  <joint name="$odonata/rotor_2_joint" type="continuous">
    <origin rpy="0 0 0" xyz="0 0 0.073"/>
    <axis xyz="0 0 1"/>
    <!-- TODO(ff): not currently set because it's not yet supported -->
    <!-- <limit effort="2000" velocity="${max_rot_velocity}" /> -->
    <parent link="right_motor"/>
    <child link="$odonata/rotor_2"/>
  </joint>
  <link name="$odonata/rotor_2">
    <inertial>
      <mass value="0.005"/>
      <!-- [kg] -->
      <inertia ixx="9.7499961e-07" ixy="0.0" ixz="0.0" iyy="0.000172080097835" iyz="0.0" izz="0.000172980097475"/>
    </inertial>
    <visual>
      <geometry>
        <mesh filename="package://rotors_description/meshes/propeller_cw.dae" scale="0.2032 0.2032 0.2032"/>
        <!-- The propeller meshes have a radius of 1m -->
        <!-- <box size="${2*radius_rotor} 0.01 0.005"/> -->
      </geometry>
    </visual>
    <collision>
      <geometry>
        <cylinder length="0.005" radius="0.2032"/>
        <!-- [m] -->
      </geometry>
    </collision>
  </link>
  <gazebo>
    <plugin filename="librotors_gazebo_motor_model.so" name="$odonata_right_top_motor_model">
      <robotNamespace>$odonata</robotNamespace>
      <jointName>$odonata/rotor_2_joint</jointName>
      <linkName>$odonata/rotor_2</linkName>
      <turningDirection>cw</turningDirection>
      <timeConstantUp>0.0125</timeConstantUp>
      <timeConstantDown>0.025</timeConstantDown>
      <maxRotVelocity>838</maxRotVelocity>
      <motorConstant>8.54858e-06</motorConstant>
      <momentConstant>0.016</momentConstant>
      <commandSubTopic>gazebo/command/motor_speed</commandSubTopic>
      <motorNumber>2</motorNumber>
      <rotorDragCoefficient>8.06428e-05</rotorDragCoefficient>
      <rollingMomentCoefficient>1e-06</rollingMomentCoefficient>
      <motorSpeedPubTopic>motor_speed/2</motorSpeedPubTopic>
      <rotorVelocitySlowdownSim>10</rotorVelocitySlowdownSim>
    </plugin>
  </gazebo>
  <gazebo reference="$odonata/rotor_2">
    <material>Gazebo/Blue</material>
  </gazebo>
  <joint name="$odonata/rotor_3_joint" type="continuous">
    <origin rpy="0 0 0" xyz="0 0 -0.053"/>
    <axis xyz="0 0 1"/>
    <!-- TODO(ff): not currently set because it's not yet supported -->
    <!-- <limit effort="2000" velocity="${max_rot_velocity}" /> -->
    <parent link="right_motor"/>
    <child link="$odonata/rotor_3"/>
  </joint>
  <link name="$odonata/rotor_3">
    <inertial>
      <mass value="0.005"/>
      <!-- [kg] -->
      <inertia ixx="9.7499961e-07" ixy="0.0" ixz="0.0" iyy="0.000172080097835" iyz="0.0" izz="0.000172980097475"/>
    </inertial>
    <visual>
      <geometry>
        <mesh filename="package://rotors_description/meshes/propeller_ccw.dae" scale="0.2032 0.2032 0.2032"/>
        <!-- The propeller meshes have a radius of 1m -->
        <!-- <box size="${2*radius_rotor} 0.01 0.005"/> -->
      </geometry>
    </visual>
    <collision>
      <geometry>
        <cylinder length="0.005" radius="0.2032"/>
        <!-- [m] -->
      </geometry>
    </collision>
  </link>
  <gazebo>
    <plugin filename="librotors_gazebo_motor_model.so" name="$odonata_right_bottom_motor_model">
      <robotNamespace>$odonata</robotNamespace>
      <jointName>$odonata/rotor_3_joint</jointName>
      <linkName>$odonata/rotor_3</linkName>
      <turningDirection>ccw</turningDirection>
      <timeConstantUp>0.0125</timeConstantUp>
      <timeConstantDown>0.025</timeConstantDown>
      <maxRotVelocity>838</maxRotVelocity>
      <motorConstant>8.54858e-06</motorConstant>
      <momentConstant>0.016</momentConstant>
      <commandSubTopic>gazebo/command/motor_speed</commandSubTopic>
      <motorNumber>3</motorNumber>
      <rotorDragCoefficient>8.06428e-05</rotorDragCoefficient>
      <rollingMomentCoefficient>1e-06</rollingMomentCoefficient>
      <motorSpeedPubTopic>motor_speed/3</motorSpeedPubTopic>
      <rotorVelocitySlowdownSim>10</rotorVelocitySlowdownSim>
    </plugin>
  </gazebo>
  <gazebo reference="$odonata/rotor_3">
    <material>Gazebo/Red</material>
  </gazebo>
  <joint name="$odonata/rotor_4_joint" type="continuous">
    <origin rpy="0 0 0" xyz="-0.8 0 0.0543"/>
    <axis xyz="0 0 1"/>
    <!-- TODO(ff): not currently set because it's not yet supported -->
    <!-- <limit effort="2000" velocity="${max_rot_velocity}" /> -->
    <parent link="base_link"/>
    <child link="$odonata/rotor_4"/>
  </joint>
  <link name="$odonata/rotor_4">
    <inertial>
      <mass value="0.005"/>
      <!-- [kg] -->
      <inertia ixx="9.7499961e-07" ixy="0.0" ixz="0.0" iyy="0.000172080097835" iyz="0.0" izz="0.000172980097475"/>
    </inertial>
    <visual>
      <geometry>
        <mesh filename="package://rotors_description/meshes/propeller_ccw.dae" scale="0.1016 0.1016 0.1016"/>
        <!-- The propeller meshes have a radius of 1m -->
        <!-- <box size="${2*radius_rotor} 0.01 0.005"/> -->
      </geometry>
    </visual>
    <collision>
      <geometry>
        <cylinder length="0.005" radius="0.1016"/>
        <!-- [m] -->
      </geometry>
    </collision>
  </link>
  <gazebo>
    <plugin filename="librotors_gazebo_motor_model.so" name="$odonata_tail_motor_model">
      <robotNamespace>$odonata</robotNamespace>
      <jointName>$odonata/rotor_4_joint</jointName>
      <linkName>$odonata/rotor_4</linkName>
      <turningDirection>ccw</turningDirection>
      <timeConstantUp>0.0125</timeConstantUp>
      <timeConstantDown>0.025</timeConstantDown>
      <maxRotVelocity>838</maxRotVelocity>
      <motorConstant>8.54858e-06</motorConstant>
      <momentConstant>0.016</momentConstant>
      <commandSubTopic>gazebo/command/motor_speed</commandSubTopic>
      <motorNumber>4</motorNumber>
      <rotorDragCoefficient>8.06428e-05</rotorDragCoefficient>
      <rollingMomentCoefficient>1e-06</rollingMomentCoefficient>
      <motorSpeedPubTopic>motor_speed/4</motorSpeedPubTopic>
      <rotorVelocitySlowdownSim>10</rotorVelocitySlowdownSim>
    </plugin>
  </gazebo>
  <gazebo reference="$odonata/rotor_4">
    <material>Gazebo/Red</material>
  </gazebo>
</robot>
